Workbook

Sheet README
B3: Exploratory Data Analysis of Retail Sales Data
B5: Project Overview
B6: This project performs exploratory data analysis on retail sales data to identify customer demographics, purchasing behavior, and revenue trends using Microsoft Excel.
B8: Dataset Summary
B9: • 200 transaction records
B10: • Customer demographics: Age, Gender
B11: • Sales data: Product Category, Purchase Amount, Purchase Date
B13: Analysis Performed
B14: • Data cleaning and preparation
B15: • Descriptive statistics
B16: • Pivot table analysis and visualization
B18: Outputs
... B20: • Presentation slides summarizing insights

Sheet raw_sales_dataset
A1: Customer_ID | B1: Age | C1: Gender | D1: Product_Category | E1: Purchase_Amount_RM | F1: Purchase_Date
A2: 1 | B2: 28 | C2: Female | D2: Electronics | E2: 75 | F2: 45292
A3: 2 | C3: Male | D3: Sports | E3: 75 | F3: 45293
A4: 3 | B4: 35 | C4: Male | D4: Clothing | E4: 75 | F4: 45294
A5: 4 | B5: 30 | C5: Female | D5: Beauty | E5: 50 | F5: 45295
A6: 5 | B6: 22 | C6: Female | D6: Clothing | E6: 50 | F6: 45296
A7: 6 | B7: 22 | C7: Male | D7: Beauty | E7: 100 | F7: 45297
A8: 7 | B8: 18 | C8: Male | D8: Clothing | E8: 75 | F8: 45298
A9: 8 | B9: 40 | C9: Female | D9: Electronics | E9: 100 | F9: 45299
A10: 9 | B10: 30 | C10: Male | D10: Sports | E10: 150 | F10: 45300
A11: 10 | B11: 35 | C11: Male | D11: Electronics | E11: 150 | F11: 45301
A12: 11 | B12: 18 | C12: Female | D12: Clothing | E12: 50 | F12: 45302
A13: 12 | C13: Female | E13: 200 | F13: 45303
A14: 13 | B14: 40 | C14: Female | E14: 150 | F14: 45304
A15: 14 | B15: 25 | C15: Male | D15: Home | E15: 50 | F15: 45305
A16: 15 | B16: 22 | C16: Female | D16: Home | E16: 300 | F16: 45306
A17: 16 | B17: 22 | C17: Male | D17: Clothing | E17: 300 | F17: 45307
A18: 17 | B18: 25 | C18: Male | D18: Electronics | E18: 50 | F18: 45308
A19: 18 | B19: 30 | C19: Female | D19: Clothing | E19: 75 | F19: 45309
A20: 19 | B20: 28 | C20: Female | D20: Home | E20: 200 | F20: 45310
A21: 20 | B21: 25 | C21: Female | D21: Beauty | E21: 200 | F21: 45311
A22: 21 | B22: 30 | C22: Female | D22: Beauty | E22: 75 | F22: 45312
A23: 22 | B23: 22 | C23: Female | D23: Beauty | E23: 75 | F23: 45313
A24: 23 | B24: 25 | C24: Male | D24: Electronics | E24: 100 | F24: 45314
A25: 24 | B25: 28 | C25: Male | D25: Clothing | E25: 100 | F25: 45315
A26: 25 | B26: 28 | C26: Male | D26: Electronics | E26: 150 | F26: 45316
A27: 26 | B27: 35 | C27: Male | D27: Clothing | E27: 100 | F27: 45317
A28: 27 | B28: 22 | D28: Clothing | E28: 100 | F28: 45318
A29: 28 | B29: 30 | C29: Male | D29: Beauty | E29: 200 | F29: 45319
A30: 29 | B30: 30 | C30: Female | D30: Clothing | E30: 50 | F30: 45320
A31: 30 | B31: 18 | C31: Female | D31: Electronics | E31: 75 | F31: 45321
A32: 31 | B32: 30 | C32: Female | D32: Electronics | E32: 200 | F32: 45322
A33: 32 | B33: 22 | C33: Female | D33: Beauty | E33: 300 | F33: 45323
A34: 33 | B34: 18 | C34: Female | D34: Home | E34: 150 | F34: 45324
A35: 34 | B35: 45 | C35: Female | D35: Electronics | E35: 150 | F35: 45325
A36: 35 | C36: Male | D36: Electronics | E36: 50 | F36: 45326
A37: 36 | B37: 40 | C37: Female | D37: Home | E37: 100 | F37: 45327
A38: 37 | B38: 25 | C38: Male | D38: Electronics | E38: 150 | F38: 45328
A39: 38 | B39: 22 | C39: Male | D39: Beauty | E39: 75 | F39: 45329
A40: 39 | B40: 35 | C40: Female | D40: Home | E40: 75 | F40: 45330
...

Sheet cleaned_sales_dataset
A1: Customer_ID | B1: Age | C1: Gender | D1: Product_Category | E1: Purchase_Amount_RM | F1: Purchase_Date | G1: Age_Group | H1: Purchase_Band
A2: 1 | B2: 28 | C2: Female | D2: Electronics | E2: 75 | F2: 45292 | G2: =IF(B2<25,"18–24",IF(B2<35,"25–34",IF(B2<45,"35–44","45+"))) -> 25–34 | H2: =IF(E2<100,"Low",IF(E2<=250,"Medium","High")) -> Low
A3: 2 | B3: 28 | C3: Male | D3: Sports | E3: 75 | F3: 45293 | G3: =IF(B3<25,"18–24",IF(B3<35,"25–34",IF(B3<45,"35–44","45+"))) -> 25–34 | H3: =IF(E3<100,"Low",IF(E3<=250,"Medium","High")) -> Low
A4: 3 | B4: 35 | C4: Male | D4: Clothing | E4: 75 | F4: 45294 | G4: =IF(B4<25,"18–24",IF(B4<35,"25–34",IF(B4<45,"35–44","45+"))) -> 35–44 | H4: =IF(E4<100,"Low",IF(E4<=250,"Medium","High")) -> Low
A5: 4 | B5: 30 | C5: Female | D5: Beauty | E5: 50 | F5: 45295 | G5: =IF(B5<25,"18–24",IF(B5<35,"25–34",IF(B5<45,"35–44","45+"))) -> 25–34 | H5: =IF(E5<100,"Low",IF(E5<=250,"Medium","High")) -> Low
A6: 5 | B6: 22 | C6: Female | D6: Clothing | E6: 50 | F6: 45296 | G6: =IF(B6<25,"18–24",IF(B6<35,"25–34",IF(B6<45,"35–44","45+"))) -> 18–24 | H6: =IF(E6<100,"Low",IF(E6<=250,"Medium","High")) -> Low
A7: 6 | B7: 22 | C7: Male | D7: Beauty | E7: 100 | F7: 45297 | G7: =IF(B7<25,"18–24",IF(B7<35,"25–34",IF(B7<45,"35–44","45+"))) -> 18–24 | H7: =IF(E7<100,"Low",IF(E7<=250,"Medium","High")) -> Medium
A8: 7 | B8: 18 | C8: Male | D8: Clothing | E8: 75 | F8: 45298 | G8: =IF(B8<25,"18–24",IF(B8<35,"25–34",IF(B8<45,"35–44","45+"))) -> 18–24 | H8: =IF(E8<100,"Low",IF(E8<=250,"Medium","High")) -> Low
A9: 8 | B9: 40 | C9: Female | D9: Electronics | E9: 100 | F9: 45299 | G9: =IF(B9<25,"18–24",IF(B9<35,"25–34",IF(B9<45,"35–44","45+"))) -> 35–44 | H9: =IF(E9<100,"Low",IF(E9<=250,"Medium","High")) -> Medium
A10: 9 | B10: 30 | C10: Male | D10: Sports | E10: 150 | F10: 45300 | G10: =IF(B10<25,"18–24",IF(B10<35,"25–34",IF(B10<45,"35–44","45+"))) -> 25–34 | H10: =IF(E10<100,"Low",IF(E10<=250,"Medium","High")) -> Medium
A11: 10 | B11: 35 | C11: Male | D11: Electronics | E11: 150 | F11: 45301 | G11: =IF(B11<25,"18–24",IF(B11<35,"25–34",IF(B11<45,"35–44","45+"))) -> 35–44 | H11: =IF(E11<100,"Low",IF(E11<=250,"Medium","High")) -> Medium
A12: 11 | B12: 18 | C12: Female | D12: Clothing | E12: 50 | F12: 45302 | G12: =IF(B12<25,"18–24",IF(B12<35,"25–34",IF(B12<45,"35–44","45+"))) -> 18–24 | H12: =IF(E12<100,"Low",IF(E12<=250,"Medium","High")) -> Low
A13: 12 | B13: 28 | C13: Female | D13: NA | E13: 200 | F13: 45303 | G13: =IF(B13<25,"18–24",IF(B13<35,"25–34",IF(B13<45,"35–44","45+"))) -> 25–34 | H13: =IF(E13<100,"Low",IF(E13<=250,"Medium","High")) -> Medium
... A201: 200 | B201: 35 | C201: Female | D201: Electronics | E201: 300 | F201: 45491 | G201: =IF(B201<25,"18–24",IF(B201<35,"25–34",IF(B201<45,"35–44","45+"))) -> 35–44 | H201: =IF(E201<100,"Low",IF(E201<=250,"Medium","High")) -> High

Sheet Descriptive_Statistics
B4: Statistic | C4: Age | D4: Purchase_Amount_RM
B5: Count | C5: =COUNT(cleaned_sales_dataset!B2:B211) -> 200 | D5: =COUNT(cleaned_sales_dataset!E2:E211) -> 200
B6: Mean | C6: =AVERAGE(cleaned_sales_dataset!B2:B211) -> 29.195 | D6: =AVERAGE(cleaned_sales_dataset!E2:E211) -> 137
B7: Median | C7: =MEDIAN(cleaned_sales_dataset!B2:B211) -> 28 | D7: =MEDIAN(cleaned_sales_dataset!E2:E211) -> 100
B8: Min | C8: =MIN(cleaned_sales_dataset!B2:B211) -> 18 | D8: =MIN(cleaned_sales_dataset!E2:E211) -> 50
B9: Max | C9: =MAX(cleaned_sales_dataset!B2:B211) -> 45 | D9: =MAX(cleaned_sales_dataset!E2:E211) -> 500

Sheet Gender_Analysis
A3: Row Labels | B3: Count of Customer_ID
A4: Female | B4: 0.515
A5: Male | B5: 0.435
A6: NA | B6: 0.05
A7: Grand Total | B7: 1

Sheet Product_Analysis
A3: Row Labels | B3: Count of Customer_ID
A4: Beauty | B4: 0.155
A5: Clothing | B5: 0.235
A6: Electronics | B6: 0.28
A7: Home | B7: 0.18
A8: NA | B8: 0.09
A9: Sports | B9: 0.06
A10: Grand Total | B10: 1

Sheet Purchase_Analysis
A3: Row Labels | B3: Count of Customer_ID
A4: High | B4: 0.11
A5: Low | B5: 0.33
A6: Medium | B6: 0.56
A7: Grand Total | B7: 1

Sheet Age_Analysis
A3: Row Labels | B3: Count of Customer_ID
A4: 18–24 | B4: 46
A5: 25–34 | B5: 96
A6: 35–44 | B6: 47
A7: 45+ | B7: 11
A8: Grand Total | B8: 200

Sheet Avg_Purchase_By_Age
A3: Row Labels | B3: Average of Purchase_Amount_RM
A4: 35–44 | B4: 148.93617
A5: 18–24 | B5: 146.19565
A6: 25–34 | B6: 130.20833
A7: 45+ | B7: 106.81818
A8: Grand Total | B8: 137

Sheet Revenue_By_Product
A3: Row Labels | B3: Sum of Purchase_Amount_RM
A4: Sports | B4: 1800
A5: NA | B5: 2700
A6: Beauty | B6: 4425
A7: Home | B7: 5125
A8: Clothing | B8: 6100
A9: Electronics | B9: 7250
A10: Grand Total | B10: 27400

Sheet Revenue_By_Gender
A3: Row Labels | B3: Sum of Purchase_Amount_RM
A4: Female | B4: 0.53832117
A5: Male | B5: 0.41514599
A6: NA | B6: 0.046532847
A7: Grand Total | B7: 1

Sheet Monthly_Sales_Trend
A3: Row Labels | B3: Sum of Purchase_Amount_RM
A4: Jan | B4: 3700
A5: Feb | B5: 3600
A6: Mar | B6: 4125
A7: Apr | B7: 4150
A8: May | B8: 4525
A9: Jun | B9: 4325
A10: Jul | B10: 2975
A11: Grand Total | B11: 27400
